<?xml version="1.0" ?>
<robot name="turtlebot3_waffle_pi" xmlns:xacro="http://ros.org/wiki/xacro">
    
 <xacro:include filename="$(find turtlebot3_description)/urdf/common_properties.urdf"/>
  
 <xacro:arg name="laser_visual"  default="false"/>
 <xacro:arg name="camera_visual" default="false"/>
 <xacro:arg name="imu_visual"    default="false"/>
 <xacro:arg name="prefix"    default=""/>
 
  <gazebo reference="$(arg prefix)base_link">
    <material>Gazebo/DarkGrey</material>
  </gazebo>

  <gazebo reference="$(arg prefix)wheel_left_link">
    <mu1>0.1</mu1>
    <mu2>0.1</mu2>
    <kp>500000.0</kp>
    <kd>10.0</kd>
    <minDepth>0.001</minDepth>
    <maxVel>0.1</maxVel>
    <fdir1>1 0 0</fdir1>
    <material>Gazebo/FlatBlack</material>
  </gazebo>

  <gazebo reference="$(arg prefix)wheel_right_link">
    <mu1>0.1</mu1>
    <mu2>0.1</mu2>
    <kp>500000.0</kp>
    <kd>10.0</kd>
    <minDepth>0.001</minDepth>
    <maxVel>0.1</maxVel>
    <fdir1>1 0 0</fdir1>
    <material>Gazebo/FlatBlack</material>
  </gazebo>

  <gazebo reference="$(arg prefix)caster_back_right_link">
    <mu1>0.1</mu1>
    <mu2>0.1</mu2>
    <kp>1000000.0</kp>
    <kd>100.0</kd>
    <minDepth>0.001</minDepth>
    <maxVel>1.0</maxVel>
    <material>Gazebo/FlatBlack</material>
  </gazebo>

  <gazebo reference="$(arg prefix)caster_back_left_link">
    <mu1>0.1</mu1>
    <mu2>0.1</mu2>
    <kp>1000000.0</kp>
    <kd>100.0</kd>
    <minDepth>0.001</minDepth>
    <maxVel>1.0</maxVel>
    <material>Gazebo/FlatBlack</material>
  </gazebo>

  <gazebo reference="$(arg prefix)imu_link">
    <sensor type="imu" name="imu">
      <always_on>true</always_on>
      <visualize>$(arg imu_visual)</visualize>
    </sensor>
    <material>Gazebo/Grey</material>
  </gazebo>

  <gazebo>
    <plugin name="turtlebot3_waffle_pi_controller" filename="libgazebo_ros_diff_drive.so">
      <commandTopic>cmd_vel</commandTopic>
      <odometryTopic>odom</odometryTopic>
      <odometryFrame>$(arg prefix)odom</odometryFrame>
      <odometrySource>world</odometrySource>
      <publishOdomTF>true</publishOdomTF>
      <robotBaseFrame>$(arg prefix)base_footprint</robotBaseFrame>
      <publishWheelTF>false</publishWheelTF>
      <publishTf>true</publishTf>
      <publishWheelJointState>true</publishWheelJointState>
      <legacyMode>false</legacyMode>
      <updateRate>30</updateRate>
      <leftJoint>wheel_left_joint</leftJoint>
      <rightJoint>wheel_right_joint</rightJoint>
      <wheelSeparation>0.287</wheelSeparation>
      <wheelDiameter>0.066</wheelDiameter>
      <wheelAcceleration>1</wheelAcceleration>
      <wheelTorque>10</wheelTorque>
      <rosDebugLevel>na</rosDebugLevel>
    </plugin>
  </gazebo>

  <gazebo>
    <plugin name="imu_plugin" filename="libgazebo_ros_imu.so">
      <alwaysOn>true</alwaysOn>
      <bodyName>$(arg prefix)imu_link</bodyName>
      <frameName>$(arg prefix)imu_link</frameName>
      <topicName>imu</topicName>
      <serviceName>imu_service</serviceName>
      <gaussianNoise>0.0</gaussianNoise>
      <updateRate>200</updateRate>
      <imu>
        <noise>
          <type>gaussian</type>
          <rate>
            <mean>0.0</mean>
            <stddev>2e-4</stddev>
            <bias_mean>0.0000075</bias_mean>
            <bias_stddev>0.0000008</bias_stddev>
          </rate>
          <accel>
            <mean>0.0</mean>
            <stddev>1.7e-2</stddev>
            <bias_mean>0.1</bias_mean>
            <bias_stddev>0.001</bias_stddev>
          </accel>
        </noise>
      </imu>
    </plugin>
  </gazebo>

  <gazebo reference="$(arg prefix)base_scan">
    <material>Gazebo/FlatBlack</material>
    <sensor type="ray" name="lds_lfcd_sensor">
      <pose>0 0 0 0 0 0</pose>
      <visualize>$(arg laser_visual)</visualize>
      <update_rate>5</update_rate>
      <ray>
        <scan>
          <horizontal>
            <samples>360</samples>
            <resolution>1</resolution>
            <min_angle>0.0</min_angle>
            <max_angle>6.28319</max_angle>
          </horizontal>
        </scan>
        <range>
          <min>0.120</min>
          <max>3.5</max>
          <resolution>0.015</resolution>
        </range>
        <noise>
          <type>gaussian</type>
          <mean>0.0</mean>
          <stddev>0.01</stddev>
        </noise>
      </ray>
      <plugin name="gazebo_ros_lds_lfcd_controller" filename="libgazebo_ros_laser.so">
        <topicName>scan</topicName>
        <frameName>$(arg prefix)base_scan</frameName>
      </plugin>
    </sensor>
  </gazebo>

  <gazebo reference="$(arg prefix)camera_rgb_frame">
    <sensor type="camera" name="Pi Camera">
      <always_on>true</always_on>
      <visualize>$(arg camera_visual)</visualize>
      <camera>
          <horizontal_fov>1.085595</horizontal_fov>
          <image>
              <width>640</width>
              <height>480</height>
              <format>R8G8B8</format>
          </image>
          <clip>
              <near>0.03</near>
              <far>100</far>
          </clip>
      </camera>
      <plugin name="camera_controller" filename="libgazebo_ros_camera.so">
        <alwaysOn>true</alwaysOn>
        <updateRate>30.0</updateRate>
        <cameraName>camera</cameraName>
        <frameName>$(arg prefix)camera_rgb_optical_frame</frameName>
        <imageTopicName>rgb/image_raw</imageTopicName>
        <cameraInfoTopicName>rgb/camera_info</cameraInfoTopicName>
        <hackBaseline>0.07</hackBaseline>
        <distortionK1>0.0</distortionK1>
        <distortionK2>0.0</distortionK2>
        <distortionK3>0.0</distortionK3>
        <distortionT1>0.0</distortionT1>
        <distortionT2>0.0</distortionT2>
      </plugin>
    </sensor>
  </gazebo>
  
  <link name="$(arg prefix)base_footprint"/>

  <joint name="base_joint" type="fixed">
    <parent link="$(arg prefix)base_footprint"/>
    <child link="$(arg prefix)base_link" />
    <origin xyz="0 0 0.010" rpy="0 0 0"/>
  </joint>

  <link name="$(arg prefix)base_link">
    <visual>
      <origin xyz="-0.064 0 0.0" rpy="0 0 0"/>
      <geometry>
        <mesh filename="package://turtlebot3_description/meshes/bases/waffle_pi_base.stl" scale="0.001 0.001 0.001"/>
      </geometry>
      <material name="light_black"/>
    </visual>

    <collision>
      <origin xyz="-0.064 0 0.047" rpy="0 0 0"/>
      <geometry>
        <box size="0.266 0.266 0.094"/>
      </geometry>
    </collision>

    <inertial>
      <origin xyz="0 0 0" rpy="0 0 0"/>
      <mass value="1.3729096e+00"/>
      <inertia ixx="8.7002718e-03" ixy="-4.7576583e-05" ixz="1.1160499e-04"
               iyy="8.6195418e-03" iyz="-3.5422299e-06"
               izz="1.4612727e-02" />
    </inertial>
  </link>

  <joint name="wheel_left_joint" type="continuous">
    <parent link="$(arg prefix)base_link"/>
    <child link="$(arg prefix)wheel_left_link"/>
    <origin xyz="0.0 0.144 0.023" rpy="-1.57 0 0"/>
    <axis xyz="0 0 1"/>
  </joint>

  <link name="$(arg prefix)wheel_left_link">
    <visual>
      <origin xyz="0 0 0" rpy="1.57 0 0"/>
      <geometry>
        <mesh filename="package://turtlebot3_description/meshes/wheels/left_tire.stl" scale="0.001 0.001 0.001"/>
      </geometry>
      <material name="dark"/>
    </visual>

    <collision>
      <origin xyz="0 0 0" rpy="0 0 0"/>
      <geometry>
        <cylinder length="0.018" radius="0.033"/>
      </geometry>
    </collision>

    <inertial>
      <origin xyz="0 0 0" />
      <mass value="2.8498940e-02" />
      <inertia ixx="1.1175580e-05" ixy="-4.2369783e-11" ixz="-5.9381719e-09"
               iyy="1.1192413e-05" iyz="-1.4400107e-11"
               izz="2.0712558e-05" />
      </inertial>
  </link>

  <joint name="wheel_right_joint" type="continuous">
    <parent link="$(arg prefix)base_link"/>
    <child link="$(arg prefix)wheel_right_link"/>
    <origin xyz="0.0 -0.144 0.023" rpy="-1.57 0 0"/>
    <axis xyz="0 0 1"/>
  </joint>

  <link name="$(arg prefix)wheel_right_link">
    <visual>
      <origin xyz="0 0 0" rpy="1.57 0 0"/>
      <geometry>
        <mesh filename="package://turtlebot3_description/meshes/wheels/right_tire.stl" scale="0.001 0.001 0.001"/>
      </geometry>
      <material name="dark"/>
    </visual>

    <collision>
      <origin xyz="0 0 0" rpy="0 0 0"/>
      <geometry>
        <cylinder length="0.018" radius="0.033"/>
      </geometry>
    </collision>

    <inertial>
      <origin xyz="0 0 0" />
      <mass value="2.8498940e-02" />
      <inertia ixx="1.1175580e-05" ixy="-4.2369783e-11" ixz="-5.9381719e-09"
               iyy="1.1192413e-05" iyz="-1.4400107e-11"
               izz="2.0712558e-05" />
      </inertial>
  </link>

  <joint name="caster_back_right_joint" type="fixed">
    <parent link="$(arg prefix)base_link"/>
    <child link="$(arg prefix)caster_back_right_link"/>
    <origin xyz="-0.177 -0.064 -0.004" rpy="-1.57 0 0"/>
  </joint>

  <link name="$(arg prefix)caster_back_right_link">
    <collision>
      <origin xyz="0 0.001 0" rpy="0 0 0"/>
      <geometry>
        <box size="0.030 0.009 0.020"/>
      </geometry>
    </collision>

    <inertial>
      <origin xyz="0 0 0" />
      <mass value="0.005" />
      <inertia ixx="0.001" ixy="0.0" ixz="0.0"
               iyy="0.001" iyz="0.0"
               izz="0.001" />
    </inertial>
  </link>

  <joint name="caster_back_left_joint" type="fixed">
    <parent link="$(arg prefix)base_link"/>
    <child link="$(arg prefix)caster_back_left_link"/>
    <origin xyz="-0.177 0.064 -0.004" rpy="-1.57 0 0"/>
  </joint>

  <link name="$(arg prefix)caster_back_left_link">
    <collision>
      <origin xyz="0 0.001 0" rpy="0 0 0"/>
      <geometry>
        <box size="0.030 0.009 0.020"/>
      </geometry>
    </collision>

    <inertial>
      <origin xyz="0 0 0" />
      <mass value="0.005" />
      <inertia ixx="0.001" ixy="0.0" ixz="0.0"
               iyy="0.001" iyz="0.0"
               izz="0.001" />
    </inertial>
  </link>

  <joint name="imu_joint" type="fixed">
    <parent link="$(arg prefix)base_link"/>
    <child link="$(arg prefix)imu_link"/>
    <origin xyz="0.0 0 0.068" rpy="0 0 0"/>
  </joint>

  <link name="$(arg prefix)imu_link"/>

  <joint name="scan_joint" type="fixed">
    <parent link="$(arg prefix)base_link"/>
    <child link="$(arg prefix)base_scan"/>
    <origin xyz="-0.064 0 0.122" rpy="0 0 0"/>
  </joint>

  <link name="$(arg prefix)base_scan">
    <visual>
      <origin xyz="0 0 0.0" rpy="0 0 0"/>
      <geometry>
        <mesh filename="package://turtlebot3_description/meshes/sensors/lds.stl" scale="0.001 0.001 0.001"/>
      </geometry>
      <material name="dark"/>
    </visual>

    <collision>
      <origin xyz="0.015 0 -0.0065" rpy="0 0 0"/>
      <geometry>
        <cylinder length="0.0315" radius="0.055"/>
      </geometry>
    </collision>

    <inertial>
      <mass value="0.114" />
      <origin xyz="0 0 0" />
      <inertia ixx="0.001" ixy="0.0" ixz="0.0"
               iyy="0.001" iyz="0.0"
               izz="0.001" />
    </inertial>
  </link>

  <joint name="camera_joint" type="fixed">
    <origin xyz="0.073 -0.011 0.084" rpy="0 0 0"/>
    <parent link="$(arg prefix)base_link"/>
    <child link="$(arg prefix)camera_link"/>
  </joint>

  <link name="$(arg prefix)camera_link">
    <collision>
      <origin xyz="0.005 0.011 0.013" rpy="0 0 0"/>
      <geometry>
        <box size="0.015 0.030 0.027"/>
      </geometry>
    </collision>
  </link>

  <joint name="camera_rgb_joint" type="fixed">
    <origin xyz="0.003 0.011 0.009" rpy="0 0 0"/>
    <parent link="$(arg prefix)camera_link"/>
    <child link="$(arg prefix)camera_rgb_frame"/>
  </joint>
  <link name="$(arg prefix)camera_rgb_frame"/>

  <joint name="camera_rgb_optical_joint" type="fixed">
    <origin xyz="0 0 0" rpy="-1.57 0 -1.57"/>
    <parent link="$(arg prefix)camera_rgb_frame"/>
    <child link="$(arg prefix)camera_rgb_optical_frame"/>
  </joint>
  <link name="$(arg prefix)camera_rgb_optical_frame"/>

</robot>
